multiprocessing.pool.RemoteTraceback:
"""
Traceback (most recent call last):
  File "C:\Users\Administrator\AppData\Local\Programs\Python\Python35-32\lib\site-packages\requests\packages\urllib3\connection.py", line 142, in _new_conn
    (self.host, self.port), self.timeout, **extra_kw)
  File "C:\Users\Administrator\AppData\Local\Programs\Python\Python35-32\lib\site-packages\requests\packages\urllib3\util\connection.py", line 91, in create_connection
    raise err
  File "C:\Users\Administrator\AppData\Local\Programs\Python\Python35-32\lib\site-packages\requests\packages\urllib3\util\connection.py", line 81, in create_connection
    sock.connect(sa)
TimeoutError: [WinError 10060] 由于连接方在一段时间后没有正确答复或连接的主机没有反应，连接尝试失败。

During handling of the above exception, another exception occurred:

Traceback (most recent call last):
  File "C:\Users\Administrator\AppData\Local\Programs\Python\Python35-32\lib\site-packages\requests\packages\urllib3\connectionpool.py", line 578, in urlopen
    chunked=chunked)
  File "C:\Users\Administrator\AppData\Local\Programs\Python\Python35-32\lib\site-packages\requests\packages\urllib3\connectionpool.py", line 362, in _make_request
    conn.request(method, url, **httplib_request_kw)
  File "C:\Users\Administrator\AppData\Local\Programs\Python\Python35-32\lib\http\client.py", line 1083, in request
    self._send_request(method, url, body, headers)
  File "C:\Users\Administrator\AppData\Local\Programs\Python\Python35-32\lib\http\client.py", line 1128, in _send_request
    self.endheaders(body)
  File "C:\Users\Administrator\AppData\Local\Programs\Python\Python35-32\lib\http\client.py", line 1079, in endheaders
    self._send_output(message_body)
  File "C:\Users\Administrator\AppData\Local\Programs\Python\Python35-32\lib\http\client.py", line 911, in _send_output
    self.send(msg)
  File "C:\Users\Administrator\AppData\Local\Programs\Python\Python35-32\lib\http\client.py", line 854, in send
    self.connect()
  File "C:\Users\Administrator\AppData\Local\Programs\Python\Python35-32\lib\site-packages\requests\packages\urllib3\connection.py", line 167, in connect
    conn = self._new_conn()
  File "C:\Users\Administrator\AppData\Local\Programs\Python\Python35-32\lib\site-packages\requests\packages\urllib3\connection.py", line 151, in _new_conn
    self, "Failed to establish a new connection: %s" % e)
requests.packages.urllib3.exceptions.NewConnectionError: <requests.packages.urllib3.connection.HTTPConnection object at 0x02678F70>: Failed to establish a new connection: [WinError 10060] 由于连接方在一段时间后没有正确答复或连接的主机没有反应，连接尝试失败。

During handling of the above exception, another exception occurred:

Traceback (most recent call last):
  File "C:\Users\Administrator\AppData\Local\Programs\Python\Python35-32\lib\site-packages\requests\adapters.py", line 403, in send
    timeout=timeout
  File "C:\Users\Administrator\AppData\Local\Programs\Python\Python35-32\lib\site-packages\requests\packages\urllib3\connectionpool.py", line 623, in urlopen
    _stacktrace=sys.exc_info()[2])
  File "C:\Users\Administrator\AppData\Local\Programs\Python\Python35-32\lib\site-packages\requests\packages\urllib3\util\retry.py", line 281, in increment
    raise MaxRetryError(_pool, url, error or ResponseError(cause))
requests.packages.urllib3.exceptions.MaxRetryError: HTTPConnectionPool(host='bj.ganji.com', port=80): Max retries exceeded with url: /shuma/1868232000x.htm (Caused by NewConnectionError('<requests.packages.urllib3.connection.HTTPConnection object at 0x02678F70>: Failed to establish a new connection: [WinError 10060] 由于连接方在一段时间后没有正确答复或连接的主机没有反应，连接尝试失败。',))

During handling of the above exception, another exception occurred:

Traceback (most recent call last):
  File "C:\Users\Administrator\AppData\Local\Programs\Python\Python35-32\lib\multiprocessing\pool.py", line 119, in worker
    result = (True, func(*args, **kwds))
  File "C:\Users\Administrator\AppData\Local\Programs\Python\Python35-32\lib\multiprocessing\pool.py", line 44, in mapstar
    return list(map(*args))
  File "E:\python\爬虫_project\week2\week2_homework\my_ganji\pages_parsing.py", line 44, in get_item_info
    wb_data = requests.get(url)
  File "C:\Users\Administrator\AppData\Local\Programs\Python\Python35-32\lib\site-packages\requests\api.py", line 71, in get
    return request('get', url, params=params, **kwargs)
  File "C:\Users\Administrator\AppData\Local\Programs\Python\Python35-32\lib\site-packages\requests\api.py", line 57, in request
    return session.request(method=method, url=url, **kwargs)
  File "C:\Users\Administrator\AppData\Local\Programs\Python\Python35-32\lib\site-packages\requests\sessions.py", line 475, in request
    resp = self.send(prep, **send_kwargs)
  File "C:\Users\Administrator\AppData\Local\Programs\Python\Python35-32\lib\site-packages\requests\sessions.py", line 585, in send
    r = adapter.send(request, **kwargs)
  File "C:\Users\Administrator\AppData\Local\Programs\Python\Python35-32\lib\site-packages\requests\adapters.py", line 467, in send
    raise ConnectionError(e, request=request)
requests.exceptions.ConnectionError: HTTPConnectionPool(host='bj.ganji.com', port=80): Max retries exceeded with url: /shuma/1868232000x.htm (Caused by NewConnectionError('<requests.packages.urllib3.connection.HTTPConnection object at 0x02678F70>: Failed to establish a new connection: [WinError 10060] 由于连接方在一段时间后没有正确答复或连接的主机没有反应，连接尝试失败。',))
"""

The above exception was the direct cause of the following exception:

Traceback (most recent call last):
  File "E:/python/爬虫_project/week2/week2_homework/my_ganji/main.py", line 45, in <module>
    main()
  File "E:/python/爬虫_project/week2/week2_homework/my_ganji/main.py", line 40, in main
    pool.map(get_item_info, info_rst())
  File "C:\Users\Administrator\AppData\Local\Programs\Python\Python35-32\lib\multiprocessing\pool.py", line 260, in map
    return self._map_async(func, iterable, mapstar, chunksize).get()
  File "C:\Users\Administrator\AppData\Local\Programs\Python\Python35-32\lib\multiprocessing\pool.py", line 608, in get
    raise self._value
requests.exceptions.ConnectionError: None: Max retries exceeded with url: /shuma/1868232000x.htm (Caused by None)

Process finished with exit code 1